{
 "cells": [
  {
   "cell_type": "code",
   "execution_count": 8,
   "id": "a56072db",
   "metadata": {},
   "outputs": [],
   "source": [
    "from flask import Flask, render_template, redirect, url_for\n",
    "from flask_pymongo import PyMongo\n",
    "import scraping"
   ]
  },
  {
   "cell_type": "code",
   "execution_count": 9,
   "id": "2a5a83bf",
   "metadata": {},
   "outputs": [],
   "source": [
    "app = Flask(__name__)"
   ]
  },
  {
   "cell_type": "code",
   "execution_count": 10,
   "id": "9bdb6f89",
   "metadata": {},
   "outputs": [],
   "source": [
    "# Use flask_pymongo to set up mongo connection\n",
    "app.config[\"MONGO_URI\"] = \"mongodb://localhost:27017/mars_app\"\n",
    "mongo = PyMongo(app)\n"
   ]
  },
  {
   "cell_type": "code",
   "execution_count": 11,
   "id": "420f09bf",
   "metadata": {},
   "outputs": [],
   "source": [
    "@app.route(\"/\")\n",
    "def index():\n",
    "   mars = mongo.db.mars.find_one()\n",
    "   return render_template(\"index.html\", mars=mars)"
   ]
  },
  {
   "cell_type": "code",
   "execution_count": 12,
   "id": "289112c5",
   "metadata": {},
   "outputs": [],
   "source": [
    "@app.route(\"/scrape\")\n",
    "def scrape():\n",
    "   mars = mongo.db.mars\n",
    "   mars_data = scraping.scrape_all()\n",
    "   mars.update({}, mars_data, upsert=True)\n",
    "   return redirect('/', code=302)"
   ]
  },
  {
   "cell_type": "code",
   "execution_count": null,
   "id": "c2ffe404",
   "metadata": {},
   "outputs": [
    {
     "name": "stdout",
     "output_type": "stream",
     "text": [
      " * Serving Flask app '__main__' (lazy loading)\n",
      " * Environment: production\n",
      "   WARNING: This is a development server. Do not use it in a production deployment.\n",
      "   Use a production WSGI server instead.\n",
      " * Debug mode: off\n"
     ]
    },
    {
     "name": "stderr",
     "output_type": "stream",
     "text": [
      " * Running on http://127.0.0.1:5000/ (Press CTRL+C to quit)\n",
      "[2021-09-11 11:19:01,099] ERROR in app: Exception on / [GET]\n",
      "Traceback (most recent call last):\n",
      "  File \"C:\\Users\\Katelyn\\anaconda3\\envs\\PythonData\\lib\\site-packages\\flask\\app.py\", line 2070, in wsgi_app\n",
      "    response = self.full_dispatch_request()\n",
      "  File \"C:\\Users\\Katelyn\\anaconda3\\envs\\PythonData\\lib\\site-packages\\flask\\app.py\", line 1515, in full_dispatch_request\n",
      "    rv = self.handle_user_exception(e)\n",
      "  File \"C:\\Users\\Katelyn\\anaconda3\\envs\\PythonData\\lib\\site-packages\\flask\\app.py\", line 1513, in full_dispatch_request\n",
      "    rv = self.dispatch_request()\n",
      "  File \"C:\\Users\\Katelyn\\anaconda3\\envs\\PythonData\\lib\\site-packages\\flask\\app.py\", line 1499, in dispatch_request\n",
      "    return self.ensure_sync(self.view_functions[rule.endpoint])(**req.view_args)\n",
      "  File \"<ipython-input-11-e191d5b2e6ba>\", line 3, in index\n",
      "    mars = mongo.db.mars.find_one()\n",
      "  File \"C:\\Users\\Katelyn\\anaconda3\\envs\\PythonData\\lib\\site-packages\\pymongo\\collection.py\", line 1319, in find_one\n",
      "    for result in cursor.limit(-1):\n",
      "  File \"C:\\Users\\Katelyn\\anaconda3\\envs\\PythonData\\lib\\site-packages\\pymongo\\cursor.py\", line 1207, in next\n",
      "    if len(self.__data) or self._refresh():\n",
      "  File \"C:\\Users\\Katelyn\\anaconda3\\envs\\PythonData\\lib\\site-packages\\pymongo\\cursor.py\", line 1100, in _refresh\n",
      "    self.__session = self.__collection.database.client._ensure_session()\n",
      "  File \"C:\\Users\\Katelyn\\anaconda3\\envs\\PythonData\\lib\\site-packages\\pymongo\\mongo_client.py\", line 1816, in _ensure_session\n",
      "    return self.__start_session(True, causal_consistency=False)\n",
      "  File \"C:\\Users\\Katelyn\\anaconda3\\envs\\PythonData\\lib\\site-packages\\pymongo\\mongo_client.py\", line 1766, in __start_session\n",
      "    server_session = self._get_server_session()\n",
      "  File \"C:\\Users\\Katelyn\\anaconda3\\envs\\PythonData\\lib\\site-packages\\pymongo\\mongo_client.py\", line 1802, in _get_server_session\n",
      "    return self._topology.get_server_session()\n",
      "  File \"C:\\Users\\Katelyn\\anaconda3\\envs\\PythonData\\lib\\site-packages\\pymongo\\topology.py\", line 488, in get_server_session\n",
      "    None)\n",
      "  File \"C:\\Users\\Katelyn\\anaconda3\\envs\\PythonData\\lib\\site-packages\\pymongo\\topology.py\", line 217, in _select_servers_loop\n",
      "    (self._error_message(selector), timeout, self.description))\n",
      "pymongo.errors.ServerSelectionTimeoutError: localhost:27017: [WinError 10061] No connection could be made because the target machine actively refused it, Timeout: 30s, Topology Description: <TopologyDescription id: 613cd6d103144946553171d4, topology_type: Single, servers: [<ServerDescription ('localhost', 27017) server_type: Unknown, rtt: None, error=AutoReconnect('localhost:27017: [WinError 10061] No connection could be made because the target machine actively refused it')>]>\n",
      "127.0.0.1 - - [11/Sep/2021 11:19:01] \"GET / HTTP/1.1\" 500 -\n",
      "[2021-09-11 11:28:52,563] ERROR in app: Exception on / [GET]\n",
      "Traceback (most recent call last):\n",
      "  File \"C:\\Users\\Katelyn\\anaconda3\\envs\\PythonData\\lib\\site-packages\\flask\\app.py\", line 2070, in wsgi_app\n",
      "    response = self.full_dispatch_request()\n",
      "  File \"C:\\Users\\Katelyn\\anaconda3\\envs\\PythonData\\lib\\site-packages\\flask\\app.py\", line 1515, in full_dispatch_request\n",
      "    rv = self.handle_user_exception(e)\n",
      "  File \"C:\\Users\\Katelyn\\anaconda3\\envs\\PythonData\\lib\\site-packages\\flask\\app.py\", line 1513, in full_dispatch_request\n",
      "    rv = self.dispatch_request()\n",
      "  File \"C:\\Users\\Katelyn\\anaconda3\\envs\\PythonData\\lib\\site-packages\\flask\\app.py\", line 1499, in dispatch_request\n",
      "    return self.ensure_sync(self.view_functions[rule.endpoint])(**req.view_args)\n",
      "  File \"<ipython-input-11-e191d5b2e6ba>\", line 3, in index\n",
      "    mars = mongo.db.mars.find_one()\n",
      "  File \"C:\\Users\\Katelyn\\anaconda3\\envs\\PythonData\\lib\\site-packages\\pymongo\\collection.py\", line 1319, in find_one\n",
      "    for result in cursor.limit(-1):\n",
      "  File \"C:\\Users\\Katelyn\\anaconda3\\envs\\PythonData\\lib\\site-packages\\pymongo\\cursor.py\", line 1207, in next\n",
      "    if len(self.__data) or self._refresh():\n",
      "  File \"C:\\Users\\Katelyn\\anaconda3\\envs\\PythonData\\lib\\site-packages\\pymongo\\cursor.py\", line 1100, in _refresh\n",
      "    self.__session = self.__collection.database.client._ensure_session()\n",
      "  File \"C:\\Users\\Katelyn\\anaconda3\\envs\\PythonData\\lib\\site-packages\\pymongo\\mongo_client.py\", line 1816, in _ensure_session\n",
      "    return self.__start_session(True, causal_consistency=False)\n",
      "  File \"C:\\Users\\Katelyn\\anaconda3\\envs\\PythonData\\lib\\site-packages\\pymongo\\mongo_client.py\", line 1766, in __start_session\n",
      "    server_session = self._get_server_session()\n",
      "  File \"C:\\Users\\Katelyn\\anaconda3\\envs\\PythonData\\lib\\site-packages\\pymongo\\mongo_client.py\", line 1802, in _get_server_session\n",
      "    return self._topology.get_server_session()\n",
      "  File \"C:\\Users\\Katelyn\\anaconda3\\envs\\PythonData\\lib\\site-packages\\pymongo\\topology.py\", line 488, in get_server_session\n",
      "    None)\n",
      "  File \"C:\\Users\\Katelyn\\anaconda3\\envs\\PythonData\\lib\\site-packages\\pymongo\\topology.py\", line 217, in _select_servers_loop\n",
      "    (self._error_message(selector), timeout, self.description))\n",
      "pymongo.errors.ServerSelectionTimeoutError: localhost:27017: [WinError 10061] No connection could be made because the target machine actively refused it, Timeout: 30s, Topology Description: <TopologyDescription id: 613cd6d103144946553171d4, topology_type: Single, servers: [<ServerDescription ('localhost', 27017) server_type: Unknown, rtt: None, error=AutoReconnect('localhost:27017: [WinError 10061] No connection could be made because the target machine actively refused it')>]>\n",
      "127.0.0.1 - - [11/Sep/2021 11:28:52] \"GET / HTTP/1.1\" 500 -\n",
      "[2021-09-11 11:29:33,942] ERROR in app: Exception on / [GET]\n",
      "Traceback (most recent call last):\n",
      "  File \"C:\\Users\\Katelyn\\anaconda3\\envs\\PythonData\\lib\\site-packages\\flask\\app.py\", line 2070, in wsgi_app\n",
      "    response = self.full_dispatch_request()\n",
      "  File \"C:\\Users\\Katelyn\\anaconda3\\envs\\PythonData\\lib\\site-packages\\flask\\app.py\", line 1515, in full_dispatch_request\n",
      "    rv = self.handle_user_exception(e)\n",
      "  File \"C:\\Users\\Katelyn\\anaconda3\\envs\\PythonData\\lib\\site-packages\\flask\\app.py\", line 1513, in full_dispatch_request\n",
      "    rv = self.dispatch_request()\n",
      "  File \"C:\\Users\\Katelyn\\anaconda3\\envs\\PythonData\\lib\\site-packages\\flask\\app.py\", line 1499, in dispatch_request\n",
      "    return self.ensure_sync(self.view_functions[rule.endpoint])(**req.view_args)\n",
      "  File \"<ipython-input-11-e191d5b2e6ba>\", line 3, in index\n",
      "    mars = mongo.db.mars.find_one()\n",
      "  File \"C:\\Users\\Katelyn\\anaconda3\\envs\\PythonData\\lib\\site-packages\\pymongo\\collection.py\", line 1319, in find_one\n",
      "    for result in cursor.limit(-1):\n",
      "  File \"C:\\Users\\Katelyn\\anaconda3\\envs\\PythonData\\lib\\site-packages\\pymongo\\cursor.py\", line 1207, in next\n",
      "    if len(self.__data) or self._refresh():\n",
      "  File \"C:\\Users\\Katelyn\\anaconda3\\envs\\PythonData\\lib\\site-packages\\pymongo\\cursor.py\", line 1100, in _refresh\n",
      "    self.__session = self.__collection.database.client._ensure_session()\n",
      "  File \"C:\\Users\\Katelyn\\anaconda3\\envs\\PythonData\\lib\\site-packages\\pymongo\\mongo_client.py\", line 1816, in _ensure_session\n",
      "    return self.__start_session(True, causal_consistency=False)\n",
      "  File \"C:\\Users\\Katelyn\\anaconda3\\envs\\PythonData\\lib\\site-packages\\pymongo\\mongo_client.py\", line 1766, in __start_session\n",
      "    server_session = self._get_server_session()\n",
      "  File \"C:\\Users\\Katelyn\\anaconda3\\envs\\PythonData\\lib\\site-packages\\pymongo\\mongo_client.py\", line 1802, in _get_server_session\n",
      "    return self._topology.get_server_session()\n",
      "  File \"C:\\Users\\Katelyn\\anaconda3\\envs\\PythonData\\lib\\site-packages\\pymongo\\topology.py\", line 488, in get_server_session\n",
      "    None)\n",
      "  File \"C:\\Users\\Katelyn\\anaconda3\\envs\\PythonData\\lib\\site-packages\\pymongo\\topology.py\", line 217, in _select_servers_loop\n",
      "    (self._error_message(selector), timeout, self.description))\n",
      "pymongo.errors.ServerSelectionTimeoutError: localhost:27017: [WinError 10061] No connection could be made because the target machine actively refused it, Timeout: 30s, Topology Description: <TopologyDescription id: 613cd6d103144946553171d4, topology_type: Single, servers: [<ServerDescription ('localhost', 27017) server_type: Unknown, rtt: None, error=AutoReconnect('localhost:27017: [WinError 10061] No connection could be made because the target machine actively refused it')>]>\n"
     ]
    },
    {
     "name": "stderr",
     "output_type": "stream",
     "text": [
      "127.0.0.1 - - [11/Sep/2021 11:29:33] \"GET / HTTP/1.1\" 500 -\n",
      "127.0.0.1 - - [11/Sep/2021 11:29:34] \"GET /favicon.ico HTTP/1.1\" 404 -\n",
      "[2021-09-11 11:30:21,950] ERROR in app: Exception on / [GET]\n",
      "Traceback (most recent call last):\n",
      "  File \"C:\\Users\\Katelyn\\anaconda3\\envs\\PythonData\\lib\\site-packages\\flask\\app.py\", line 2070, in wsgi_app\n",
      "    response = self.full_dispatch_request()\n",
      "  File \"C:\\Users\\Katelyn\\anaconda3\\envs\\PythonData\\lib\\site-packages\\flask\\app.py\", line 1515, in full_dispatch_request\n",
      "    rv = self.handle_user_exception(e)\n",
      "  File \"C:\\Users\\Katelyn\\anaconda3\\envs\\PythonData\\lib\\site-packages\\flask\\app.py\", line 1513, in full_dispatch_request\n",
      "    rv = self.dispatch_request()\n",
      "  File \"C:\\Users\\Katelyn\\anaconda3\\envs\\PythonData\\lib\\site-packages\\flask\\app.py\", line 1499, in dispatch_request\n",
      "    return self.ensure_sync(self.view_functions[rule.endpoint])(**req.view_args)\n",
      "  File \"<ipython-input-11-e191d5b2e6ba>\", line 3, in index\n",
      "    mars = mongo.db.mars.find_one()\n",
      "  File \"C:\\Users\\Katelyn\\anaconda3\\envs\\PythonData\\lib\\site-packages\\pymongo\\collection.py\", line 1319, in find_one\n",
      "    for result in cursor.limit(-1):\n",
      "  File \"C:\\Users\\Katelyn\\anaconda3\\envs\\PythonData\\lib\\site-packages\\pymongo\\cursor.py\", line 1207, in next\n",
      "    if len(self.__data) or self._refresh():\n",
      "  File \"C:\\Users\\Katelyn\\anaconda3\\envs\\PythonData\\lib\\site-packages\\pymongo\\cursor.py\", line 1100, in _refresh\n",
      "    self.__session = self.__collection.database.client._ensure_session()\n",
      "  File \"C:\\Users\\Katelyn\\anaconda3\\envs\\PythonData\\lib\\site-packages\\pymongo\\mongo_client.py\", line 1816, in _ensure_session\n",
      "    return self.__start_session(True, causal_consistency=False)\n",
      "  File \"C:\\Users\\Katelyn\\anaconda3\\envs\\PythonData\\lib\\site-packages\\pymongo\\mongo_client.py\", line 1766, in __start_session\n",
      "    server_session = self._get_server_session()\n",
      "  File \"C:\\Users\\Katelyn\\anaconda3\\envs\\PythonData\\lib\\site-packages\\pymongo\\mongo_client.py\", line 1802, in _get_server_session\n",
      "    return self._topology.get_server_session()\n",
      "  File \"C:\\Users\\Katelyn\\anaconda3\\envs\\PythonData\\lib\\site-packages\\pymongo\\topology.py\", line 488, in get_server_session\n",
      "    None)\n",
      "  File \"C:\\Users\\Katelyn\\anaconda3\\envs\\PythonData\\lib\\site-packages\\pymongo\\topology.py\", line 217, in _select_servers_loop\n",
      "    (self._error_message(selector), timeout, self.description))\n",
      "pymongo.errors.ServerSelectionTimeoutError: localhost:27017: [WinError 10061] No connection could be made because the target machine actively refused it, Timeout: 30s, Topology Description: <TopologyDescription id: 613cd6d103144946553171d4, topology_type: Single, servers: [<ServerDescription ('localhost', 27017) server_type: Unknown, rtt: None, error=AutoReconnect('localhost:27017: [WinError 10061] No connection could be made because the target machine actively refused it')>]>\n",
      "127.0.0.1 - - [11/Sep/2021 11:30:21] \"GET / HTTP/1.1\" 500 -\n",
      "\n",
      "\n",
      "====== WebDriver manager ======\n",
      "Current google-chrome version is 93.0.4577\n",
      "Get LATEST driver version for 93.0.4577\n",
      "Get LATEST driver version for 93.0.4577\n",
      "Trying to download new driver from https://chromedriver.storage.googleapis.com/93.0.4577.63/chromedriver_win32.zip\n",
      "[2021-09-11 11:35:02,102] ERROR in app: Exception on / [GET]\n",
      "Traceback (most recent call last):\n",
      "  File \"C:\\Users\\Katelyn\\anaconda3\\envs\\PythonData\\lib\\site-packages\\flask\\app.py\", line 2070, in wsgi_app\n",
      "    response = self.full_dispatch_request()\n",
      "  File \"C:\\Users\\Katelyn\\anaconda3\\envs\\PythonData\\lib\\site-packages\\flask\\app.py\", line 1515, in full_dispatch_request\n",
      "    rv = self.handle_user_exception(e)\n",
      "  File \"C:\\Users\\Katelyn\\anaconda3\\envs\\PythonData\\lib\\site-packages\\flask\\app.py\", line 1513, in full_dispatch_request\n",
      "    rv = self.dispatch_request()\n",
      "  File \"C:\\Users\\Katelyn\\anaconda3\\envs\\PythonData\\lib\\site-packages\\flask\\app.py\", line 1499, in dispatch_request\n",
      "    return self.ensure_sync(self.view_functions[rule.endpoint])(**req.view_args)\n",
      "  File \"<ipython-input-11-e191d5b2e6ba>\", line 3, in index\n",
      "    mars = mongo.db.mars.find_one()\n",
      "  File \"C:\\Users\\Katelyn\\anaconda3\\envs\\PythonData\\lib\\site-packages\\pymongo\\collection.py\", line 1319, in find_one\n",
      "    for result in cursor.limit(-1):\n",
      "  File \"C:\\Users\\Katelyn\\anaconda3\\envs\\PythonData\\lib\\site-packages\\pymongo\\cursor.py\", line 1207, in next\n",
      "    if len(self.__data) or self._refresh():\n",
      "  File \"C:\\Users\\Katelyn\\anaconda3\\envs\\PythonData\\lib\\site-packages\\pymongo\\cursor.py\", line 1100, in _refresh\n",
      "    self.__session = self.__collection.database.client._ensure_session()\n",
      "  File \"C:\\Users\\Katelyn\\anaconda3\\envs\\PythonData\\lib\\site-packages\\pymongo\\mongo_client.py\", line 1816, in _ensure_session\n",
      "    return self.__start_session(True, causal_consistency=False)\n",
      "  File \"C:\\Users\\Katelyn\\anaconda3\\envs\\PythonData\\lib\\site-packages\\pymongo\\mongo_client.py\", line 1766, in __start_session\n",
      "    server_session = self._get_server_session()\n",
      "  File \"C:\\Users\\Katelyn\\anaconda3\\envs\\PythonData\\lib\\site-packages\\pymongo\\mongo_client.py\", line 1802, in _get_server_session\n",
      "    return self._topology.get_server_session()\n",
      "  File \"C:\\Users\\Katelyn\\anaconda3\\envs\\PythonData\\lib\\site-packages\\pymongo\\topology.py\", line 488, in get_server_session\n",
      "    None)\n",
      "  File \"C:\\Users\\Katelyn\\anaconda3\\envs\\PythonData\\lib\\site-packages\\pymongo\\topology.py\", line 217, in _select_servers_loop\n",
      "    (self._error_message(selector), timeout, self.description))\n",
      "pymongo.errors.ServerSelectionTimeoutError: localhost:27017: [WinError 10061] No connection could be made because the target machine actively refused it, Timeout: 30s, Topology Description: <TopologyDescription id: 613cd6d103144946553171d4, topology_type: Single, servers: [<ServerDescription ('localhost', 27017) server_type: Unknown, rtt: None, error=AutoReconnect('localhost:27017: [WinError 10061] No connection could be made because the target machine actively refused it')>]>\n",
      "127.0.0.1 - - [11/Sep/2021 11:35:02] \"GET / HTTP/1.1\" 500 -\n",
      "\n",
      "\n",
      "====== WebDriver manager ======\n",
      "Current google-chrome version is 93.0.4577\n",
      "Get LATEST driver version for 93.0.4577\n",
      "Get LATEST driver version for 93.0.4577\n",
      "Trying to download new driver from https://chromedriver.storage.googleapis.com/93.0.4577.63/chromedriver_win32.zip\n",
      "Driver has been saved in cache [C:\\Users\\Katelyn\\.wdm\\drivers\\chromedriver\\win32\\93.0.4577.63]\n",
      "[2021-09-11 11:36:31,497] ERROR in app: Exception on / [GET]\n",
      "Traceback (most recent call last):\n",
      "  File \"C:\\Users\\Katelyn\\anaconda3\\envs\\PythonData\\lib\\site-packages\\flask\\app.py\", line 2070, in wsgi_app\n",
      "    response = self.full_dispatch_request()\n",
      "  File \"C:\\Users\\Katelyn\\anaconda3\\envs\\PythonData\\lib\\site-packages\\flask\\app.py\", line 1515, in full_dispatch_request\n",
      "    rv = self.handle_user_exception(e)\n",
      "  File \"C:\\Users\\Katelyn\\anaconda3\\envs\\PythonData\\lib\\site-packages\\flask\\app.py\", line 1513, in full_dispatch_request\n",
      "    rv = self.dispatch_request()\n",
      "  File \"C:\\Users\\Katelyn\\anaconda3\\envs\\PythonData\\lib\\site-packages\\flask\\app.py\", line 1499, in dispatch_request\n",
      "    return self.ensure_sync(self.view_functions[rule.endpoint])(**req.view_args)\n",
      "  File \"<ipython-input-11-e191d5b2e6ba>\", line 3, in index\n",
      "    mars = mongo.db.mars.find_one()\n",
      "  File \"C:\\Users\\Katelyn\\anaconda3\\envs\\PythonData\\lib\\site-packages\\pymongo\\collection.py\", line 1319, in find_one\n",
      "    for result in cursor.limit(-1):\n",
      "  File \"C:\\Users\\Katelyn\\anaconda3\\envs\\PythonData\\lib\\site-packages\\pymongo\\cursor.py\", line 1207, in next\n",
      "    if len(self.__data) or self._refresh():\n",
      "  File \"C:\\Users\\Katelyn\\anaconda3\\envs\\PythonData\\lib\\site-packages\\pymongo\\cursor.py\", line 1100, in _refresh\n",
      "    self.__session = self.__collection.database.client._ensure_session()\n",
      "  File \"C:\\Users\\Katelyn\\anaconda3\\envs\\PythonData\\lib\\site-packages\\pymongo\\mongo_client.py\", line 1816, in _ensure_session\n",
      "    return self.__start_session(True, causal_consistency=False)\n",
      "  File \"C:\\Users\\Katelyn\\anaconda3\\envs\\PythonData\\lib\\site-packages\\pymongo\\mongo_client.py\", line 1766, in __start_session\n",
      "    server_session = self._get_server_session()\n",
      "  File \"C:\\Users\\Katelyn\\anaconda3\\envs\\PythonData\\lib\\site-packages\\pymongo\\mongo_client.py\", line 1802, in _get_server_session\n",
      "    return self._topology.get_server_session()\n",
      "  File \"C:\\Users\\Katelyn\\anaconda3\\envs\\PythonData\\lib\\site-packages\\pymongo\\topology.py\", line 488, in get_server_session\n",
      "    None)\n",
      "  File \"C:\\Users\\Katelyn\\anaconda3\\envs\\PythonData\\lib\\site-packages\\pymongo\\topology.py\", line 217, in _select_servers_loop\n",
      "    (self._error_message(selector), timeout, self.description))\n",
      "pymongo.errors.ServerSelectionTimeoutError: localhost:27017: [WinError 10061] No connection could be made because the target machine actively refused it, Timeout: 30s, Topology Description: <TopologyDescription id: 613cd6d103144946553171d4, topology_type: Single, servers: [<ServerDescription ('localhost', 27017) server_type: Unknown, rtt: None, error=AutoReconnect('localhost:27017: [WinError 10061] No connection could be made because the target machine actively refused it')>]>\n"
     ]
    },
    {
     "name": "stderr",
     "output_type": "stream",
     "text": [
      "127.0.0.1 - - [11/Sep/2021 11:36:31] \"GET / HTTP/1.1\" 500 -\n",
      "C:\\Users\\Katelyn\\anaconda3\\envs\\PythonData\\lib\\site-packages\\splinter\\driver\\webdriver\\__init__.py:530: FutureWarning: browser.find_link_by_text is deprecated. Use browser.links.find_by_text instead.\n",
      "  FutureWarning,\n",
      "C:\\Users\\Katelyn\\anaconda3\\envs\\PythonData\\lib\\site-packages\\ipykernel_launcher.py:5: DeprecationWarning: update is deprecated. Use replace_one, update_one or update_many instead.\n",
      "  \"\"\"\n",
      "[2021-09-11 11:37:14,869] ERROR in app: Exception on /scrape [GET]\n",
      "Traceback (most recent call last):\n",
      "  File \"C:\\Users\\Katelyn\\anaconda3\\envs\\PythonData\\lib\\site-packages\\flask\\app.py\", line 2070, in wsgi_app\n",
      "    response = self.full_dispatch_request()\n",
      "  File \"C:\\Users\\Katelyn\\anaconda3\\envs\\PythonData\\lib\\site-packages\\flask\\app.py\", line 1515, in full_dispatch_request\n",
      "    rv = self.handle_user_exception(e)\n",
      "  File \"C:\\Users\\Katelyn\\anaconda3\\envs\\PythonData\\lib\\site-packages\\flask\\app.py\", line 1513, in full_dispatch_request\n",
      "    rv = self.dispatch_request()\n",
      "  File \"C:\\Users\\Katelyn\\anaconda3\\envs\\PythonData\\lib\\site-packages\\flask\\app.py\", line 1499, in dispatch_request\n",
      "    return self.ensure_sync(self.view_functions[rule.endpoint])(**req.view_args)\n",
      "  File \"<ipython-input-12-def9374392f4>\", line 5, in scrape\n",
      "    mars.update({}, mars_data, upsert=True)\n",
      "  File \"C:\\Users\\Katelyn\\anaconda3\\envs\\PythonData\\lib\\site-packages\\pymongo\\collection.py\", line 3327, in update\n",
      "    write_concern, collation=collation)\n",
      "  File \"C:\\Users\\Katelyn\\anaconda3\\envs\\PythonData\\lib\\site-packages\\pymongo\\collection.py\", line 870, in _update_retryable\n",
      "    _update, session)\n",
      "  File \"C:\\Users\\Katelyn\\anaconda3\\envs\\PythonData\\lib\\site-packages\\pymongo\\mongo_client.py\", line 1497, in _retryable_write\n",
      "    with self._tmp_session(session) as s:\n",
      "  File \"C:\\Users\\Katelyn\\anaconda3\\envs\\PythonData\\lib\\contextlib.py\", line 112, in __enter__\n",
      "    return next(self.gen)\n",
      "  File \"C:\\Users\\Katelyn\\anaconda3\\envs\\PythonData\\lib\\site-packages\\pymongo\\mongo_client.py\", line 1829, in _tmp_session\n",
      "    s = self._ensure_session(session)\n",
      "  File \"C:\\Users\\Katelyn\\anaconda3\\envs\\PythonData\\lib\\site-packages\\pymongo\\mongo_client.py\", line 1816, in _ensure_session\n",
      "    return self.__start_session(True, causal_consistency=False)\n",
      "  File \"C:\\Users\\Katelyn\\anaconda3\\envs\\PythonData\\lib\\site-packages\\pymongo\\mongo_client.py\", line 1766, in __start_session\n",
      "    server_session = self._get_server_session()\n",
      "  File \"C:\\Users\\Katelyn\\anaconda3\\envs\\PythonData\\lib\\site-packages\\pymongo\\mongo_client.py\", line 1802, in _get_server_session\n",
      "    return self._topology.get_server_session()\n",
      "  File \"C:\\Users\\Katelyn\\anaconda3\\envs\\PythonData\\lib\\site-packages\\pymongo\\topology.py\", line 488, in get_server_session\n",
      "    None)\n",
      "  File \"C:\\Users\\Katelyn\\anaconda3\\envs\\PythonData\\lib\\site-packages\\pymongo\\topology.py\", line 217, in _select_servers_loop\n",
      "    (self._error_message(selector), timeout, self.description))\n",
      "pymongo.errors.ServerSelectionTimeoutError: localhost:27017: [WinError 10061] No connection could be made because the target machine actively refused it, Timeout: 30s, Topology Description: <TopologyDescription id: 613cd6d103144946553171d4, topology_type: Single, servers: [<ServerDescription ('localhost', 27017) server_type: Unknown, rtt: None, error=AutoReconnect('localhost:27017: [WinError 10061] No connection could be made because the target machine actively refused it')>]>\n",
      "127.0.0.1 - - [11/Sep/2021 11:37:14] \"GET /scrape HTTP/1.1\" 500 -\n",
      "\n",
      "\n",
      "====== WebDriver manager ======\n",
      "Current google-chrome version is 93.0.4577\n",
      "Get LATEST driver version for 93.0.4577\n"
     ]
    }
   ],
   "source": [
    "if __name__ == \"__main__\":\n",
    "   app.run()"
   ]
  },
  {
   "cell_type": "code",
   "execution_count": null,
   "id": "f732dd40",
   "metadata": {},
   "outputs": [],
   "source": []
  }
 ],
 "metadata": {
  "kernelspec": {
   "display_name": "Python 3",
   "language": "python",
   "name": "python3"
  },
  "language_info": {
   "codemirror_mode": {
    "name": "ipython",
    "version": 3
   },
   "file_extension": ".py",
   "mimetype": "text/x-python",
   "name": "python",
   "nbconvert_exporter": "python",
   "pygments_lexer": "ipython3",
   "version": "3.7.10"
  }
 },
 "nbformat": 4,
 "nbformat_minor": 5
}
